Workbook

Sheet 전체
J1: 예측 | K1: 전략수립 | L1: 실행 1M | M1: 실행 2M | N1: 실행 3M | O1: 실행 4M | P1: 실행 5M | Q1: 실행 6M
A2: 판매비와 관리비 세부 항목 | F2: 1월 | G2: 2월 | H2: 3월 | I2: 4월 | J2: ='비용통합'!P1 -> 5월(E)-절감X | K2: 6월(E) | L2: 7월(E) | M2: 8월 | N2: 9월 | O2: 10월 | P2: 11월 | Q2: 12월 | R2: 평균 | S2: 합계 | T2: 비중 | V2: Raw Data
A3: 전체 | F3: 675392140 | G3: 539468530 | H3: 497094329 | I3: 550686233 | R3: =sum(F3:I3)/4 -> 565660308 | S3: =sum(F3:Q3) -> 2262641232 | T3: - | V3: https://malgn-my.sharepoint.com/:x:/g/personal/hs_m_malgn_onmicrosoft_com/IQCZHk0IVMzcQ7M5E3NO4EoCARWbUmxSzCxcfdK-66f5sKw?rtime=ius48yW23kg
B4: 지급수수료 | F4: 27140784 | G4: 6495494 | H4: 8693153 | I4: 14803057 | J4: =sum('비용통합'!P2:P80) -> 7247347 | R4: =sum(F4:I4)/4 -> 14283122 | S4: =sum(F4:Q4) -> 64379835 | T4: =S4/$S$3 -> 0.0284534
B5: 광고선전비 | F5: 20800757 | G5: 15696145 | H5: 26020357 | I5: 21467572 | J5: =sum('비용통합'!P81:P93) -> 17601035 | R5: =sum(F5:I5)/4 -> 20996208 | S5: =sum(F5:Q5) -> 101585866 | T5: =S5/$S$3 -> 0.044897028 | V5: 손익계산서
B6: 외주비 | F6: 206834639 | G6: 206869625 | H6: 186409502 | I6: 222028710 | J6: =sum('비용통합'!P94:P130) -> 192145345 | R6: =sum(F6:I6)/4 -> 205535619 | S6: =sum(F6:Q6) -> 1014287821 | T6: =S6/$S$3 -> 0.44827603 | V6: https://malgn-my.sharepoint.com/:x:/g/personal/hs_m_malgn_onmicrosoft_com/IQA_sBbfDjd8SYUAklq37jcVAeuIEQJeeL7Ef2l0MgSN9WA?rtime=NQkFbkm23kg
B7: 소계 | F7: =SUM(F4:F6) -> 254776180 | G7: =SUM(G4:G6) -> 229061264 | H7: =SUM(H4:H6) -> 221123012 | I7: =SUM(I4:I6) -> 258299339 | J7: =SUM(J4:J6) -> 216993727 | R7: =sum(F7:I7)/4 -> 2.4081495e+08 | S7: =sum(S4:S6) -> 1180253522 | T7: =sum(T4:T6) -> 0.52162645
J8: 1~4월 평균이하로 떨어짐
A9: 회사 예측
B10: 지급수수료 | F10: 27140784 | G10: 6495494 | H10: 8693153 | I10: 14803057 | J10: 8693153
B11: 광고선전비 | F11: 20800757 | G11: 15696145 | H11: 26020357 | I11: 21467572 | J11: 26020357
B12: 건물관리비 | F12: 1382590 | G12: 1438470 | H12: 1384330 | I12: 1360340 | J12: 1384330
B13: 외주비 | F13: 206834639 | G13: 206869625 | H13: 186409502 | I13: 222028710 | J13: 186409502
B14: 소계 | F14: =SUM(F11:F13) -> 229017986 | G14: =SUM(G11:G13) -> 224004240 | H14: =SUM(H11:H13) -> 213814189 | I14: =SUM(I11:I13) -> 244856622 | J14: =SUM(J11:J13) -> 213814189

Sheet 지급수수료
B1: 구분 | C1: 내용 | D1: 거래처 | E1: 부서 | F1: 날짜 | G1: 1월 | H1: 2월 | I1: 3월 | J1: 4월 | K1: 5월 | L1: 6월 | M1: 7월 | N1: 8월 | O1: 9월 | P1: 10월 | Q1: 11월 | R1: 12월 | S1: 합계 | T1: 비중 | V1: ='전체'!S4 -> 64379835
B2: 지급수수료 | C2: 카드수수료 | D2: 카드수수료 | F2: 46023 | G2: 400 | H2: 400
B3: 지급수수료 | C3: 스탠드형 직수얼음정수기 1 | D3: SK매직(주) | F3: 46023 | G3: 42636 | H3: 42636 | I3: 42636 | J3: 42636
B4: 지급수수료 | C4: 12월 영업 대행 수수료 1 X 111,000 | D4: 주식회사 엔트위즈미디어 | F4: 46024 | G4: 111000 | H4: 109500 | I4: 109500
B5: 지급수수료 | C5: 민원발급수수료 | D5: 법원행정처 | F5: 46027 | G5: 10000 | I5: 1000 | J5: 15000
B6: 지급수수료 | C6: 민원발급수수료 | D6: （주) 엘지씨엔에스 | F6: 46050 | G6: 1700 | J6: 1000
B7: 지급수수료 | C7: 서류발급 | D7: 엔에이치엔케이씨피주식회사 | F7: 46037 | G7: 8637 | H7: 36366 | I7: 2728
B8: 지급수수료 | C8: 수수료 | D8: 킨코스코리아(주) | F8: 46040 | G8: 38310
B9: 지급수수료 | C9: 텔레캅서비스 | D9: 케이티텔레캅(주) | F9: 46027 | G9: 60000 | H9: 60000 | I9: 60000 | J9: 60000
B10: 지급수수료 | C10: 프린터 기본 임대료 | D10: 마이컴센터 | F10: 46027 | G10: 50000 | H10: 50000 | I10: 50000 | J10: 50000
B11: 지급수수료 | C11: 2026년 1월 임대 D320 | D11: 신도H렌탈 | F11: 46027 | G11: 70000 | H11: 70000 | I11: 70000 | J11: 70000
B12: 지급수수료 | C12: 원티드스페이스 월간 이용료 | D12: 나이스정보통신(주) | F12: 46027 | G12: 96000 | H12: 85000 | I12: 95285 | J12: 96160
B13: 지급수수료 | C13: 주차권구매 | D13: 대륭포스트타워1차입주자대표운영위원회 | F13: 46027 | G13: 75000 | J13: 165000
B14: 지급수수료 | C14: Adobe-회사계정 월간 구독료 | D14: 엔에이치엔케이씨피주식회사 | F14: 46028 | G14: 104000 | H14: 104000 | I14: 104000 | J14: 94546
B15: 지급수수료 | C15: 수수료 | D15: 나이스정보통신(주) | F15: 46028 | G15: 12638 | H15: 66265 | I15: 4455
B16: 지급수수료 | C16: 수수료 | D16: 주식회사 코스트제로컨설팅 | F16: 46031 | G16: 6000000
B17: 지급수수료 | C17: 수수료 | D17: 주식회사헥토파이낸셜 | F17: 46034 | G17: 145200
B18: 지급수수료 | C18: 수수료 | D18: 한국정보통신(주) | F18: 46098 | I18: 9091
B19: 지급수수료 | C19: 04월 경비청구 - 김상철 | D19: 주식회사헥토파이낸셜 | F19: 46129 | J19: 7273
B20: 지급수수료 | C20: 부스터 패키지 - 가상계좌 1 X 522,327 | D20: ㈜사람인에이치알 | F20: 46029 | G20: 522327
B21: 지급수수료 | C21: 렌탈료 1 | D21: 청호나이스(주) | F21: 46031 | G21: 45364 | H21: 45364 | I21: 45364 | J21: 45364
B22: 지급수수료 | C22: 서류 출력 | D22: 나이스정보통신(주) | F22: 46031 | G22: 5457 | H22: 23183
B23: 지급수수료 | C23: 스픽 구독 | D23: 나이스정보통신(주) | F23: 46031 | G23: 271819
B24: 지급수수료 | C24: 월구독 | D24: 쿠팡페이 주식회사 | F24: 46031 | G24: 7173 | H24: 7173 | I24: 7173 | J24: 7173
B25: 지급수수료 | C25: 쿠팡월정액 - 쿠팡월정액 | D25: 쿠팡페이 주식회사 | F25: 46121
B26: 지급수수료 | C26: SMS100***16484 | D26: 신한 100-027-164841 | F26: 46034 | G26: 3000 | H26: 3000 | I26: 3000 | J26: 3000
B27: 지급수수료 | C27: SMS수수료 | D27: 우리 1005-002-038032 | F27: 46034 | G27: 1800 | H27: 1800 | I27: 1800 | J27: 1800
B28: 지급수수료 | C28: 도메인 등록 | D28: 메가존㈜ | F28: 46036 | G28: 193200 | H28: 70000 | I28: 251791 | J28: 82000
B29: 지급수수료 | C29: MALGN.ONHIWORKS.COM 연장(하이웍스) 1 X 456,000 | D29: (주) 가비아 | F29: 46043 | G29: 456000
B30: 지급수수료 | C30: 식물관리 외 1 | D30: 플라워리치 | F30: 46045 | G30: 400000 | H30: 300000 | J30: 300000
B31: 지급수수료 | C31: 1월 기장료 | D31: 박앤장세무회계사무소 | F31: 46047 | G31: 250000 | H31: 250000 | I31: 250000 | J31: 250000
B32: 지급수수료 | C32: 2025 세무조정 | D32: 박앤장세무회계사무소 | F32: 46106 | I32: 4950000
B33: 지급수수료 | C33: Atlassian Jira(Cloud,S) | D33: 주식회사 오픈소스컨설팅 | F33: 46048 | G33: 6396000
B34: 지급수수료 | C34: Google Workspace Business Standard 연간 요금제 이용료 52 | D34: 주식회사 소프트웨어인라이프 | F34: 46050 | G34: 10083400 | I34: 175500
B35: 지급수수료 | C35: 정기청소 1 X 660,000 | D35: 탑 크린 월드 구로 | F35: 46051 | G35: 660000 | H35: 660000 | I35: 660000 | J35: 660000
B36: 지급수수료 | C36: 월배치CMS수수료-malgnlms | D36: 효성에프엠에스(주) | F36: 46052 | G36: 779765 | H36: 591018 | I36: 575868 | J36: 679578
B37: 지급수수료 | C37: 월월사용료-malgnlms | D37: 효성에프엠에스(주) | F37: 46052 | G37: 40600 | H37: 40632 | I37: 40800 | J37: 40576
B38: 지급수수료 | C38: 가상계좌 수수료대 | D38: (주)케이지모빌리언스 | F38: 46052 | G38: 250
B39: 지급수수료 | C39: 전자지불수수료(bill_wecanglr7 2026/01) | D39: 토스페이먼츠 주식회사 | F39: 46053 | G39: 133108 | H39: 158448 | I39: 360937 | J39: 53582
B40: 지급수수료 | C40: 전자지불수수료(MGN_snukorxi11 2026/02) | D40: 토스페이먼츠 주식회사 | F40: 46081 | H40: 9268 | I40: 11516 | J40: 5392
...

Sheet 외주비
B1: 구분 | C1: 내용 | D1: 거래처 | E1: 부서 | F1: 날짜 | G1: 1월 | H1: 2월 | I1: 3월 | J1: 4월 | K1: 5월 | L1: 6월 | M1: 7월 | N1: 8월 | O1: 9월 | P1: 10월 | Q1: 11월 | R1: 12월 | S1: 합계 | T1: 비중
B2: 외주비 | C2: 서버호스팅 (2026.01.01~2026.01.31) 1 | D2: (주) 비아웹 | E2: 환급 | F2: 46023 | G2: 1200000 | H2: 1200000 | I2: 1200000 | J2: 1200000
B3: 외주비 | C3: 대원제약 영업대행 수수료 | D3: ㈜키메디 | E3: 위캔디오 | F3: 46023 | G3: 460000 | H3: 460000 | I3: 460000 | J3: 460000
B4: 외주비 | C4: 한샘 영업 대행 수수료 12월 1 | D4: 주식회사 오브이엑스(OVX CO.,LTD.) | E4: 위캔디오 | F4: 46024 | G4: 367500 | H4: 367500 | I4: 367500 | J4: 367500
B5: 외주비 | C5: 동양생명 LMS 유지보수 | D5: (주)맑은에스 | E5: 범용 | F5: 46027 | G5: 1700000 | H5: 1700000 | I5: 1700000 | J5: 1700000
B6: 외주비 | C6: Managed Service외0건 | D6: (주)씨디네트웍스 | E6: 위캔디오 | F6: 46027 | G6: 1500000 | H6: 1500000 | I6: 1500000 | J6: 1500000
B7: 외주비 | C7: Rack 외 2 건외0건 | D7: (주)씨디네트웍스 | E7: 위캔디오 | F7: 46027 | G7: 15200000 | H7: 15200000 | I7: 15200000 | J7: 15200000
B8: 외주비 | C8: Media Acceleration - VoD 외 1 건외0건 | D8: (주)씨디네트웍스 | E8: 위캔디오 | F8: 46027 | G8: 1013000 | H8: 1013000 | I8: 1013000 | J8: 1013000
B9: 외주비 | C9: 기간 연장 | D9: 메가존㈜ | E9: 전사 | F9: 46027 | G9: 85000 | H9: 139200 | I9: 165000 | J9: 92720
B10: 외주비 | C10: 필더필 오아라이브 유지보수 | D10: 주식회사 그레이포인트 | E10: 위캔디오 | F10: 46027 | G10: 2231250 | H10: 2625000 | I10: 525000 | J10: 3500000
B11: 외주비 | C11: 공공LMS 위탁 운영대행 12월분 1 X 3,500,000 | D11: 주식회사 온케어 | E11: 공공 | F11: 46031 | G11: 3500000 | H11: 2900000 | I11: 3500000 | J11: 3500000
B12: 외주비 | C12: AWS 사용료_시냅스엠 1 | D12: 스마일샤크 주식회사 | E12: 위캔디오 | F12: 46032 | G12: 23035640 | H12: 17088150 | I12: 16364340 | J12: 25309380
B13: 외주비 | C13: AWS 사용료 1 | D13: 스마일샤크 주식회사 | E13: 환급 | F13: 46032 | G13: 6801660 | H13: 6997530 | I13: 6543450 | J13: 7307900
B14: 외주비 | C14: 한국어 러시아어 자막_초급/중급_완료 | D14: (주)글로벌키타(Global Kita) | E14: 전사 | F14: 46036 | G14: 10000000
B15: 외주비 | C15: NHN_Cloud_이용요금 | D15: 엔에이치엔클라우드 주식회사 | E15: 위캔디오 | F15: 46036 | G15: 5118691 | H15: 7839631 | J15: 4365111
B16: 외주비 | C16: NHN_Cloud_이용요금 | D16: 엔에이치엔클라우드 주식회사 | E16: 공공 | F16: 46036 | G16: 2707951 | H16: 2983909 | I16: 3405438 | J16: 3718937
B17: 외주비 | C17: 맑은소프트 Naver Cloud Service 36개월 이용계약_2025 1 X 8,976,870 | D17: 씨제이올리브네트웍스 주식회사 | E17: 공공 | F17: 46037 | G17: 8976870 | H17: 8772225 | I17: 8840265 | J17: 9412200
B18: 외주비 | C18: 맑은소프트 ONS CDN 서비스 1월(12월 사용분) 1 X 3,000,000 | E18: 위캔디오 | F18: 46042 | G18: 3000000
B19: 외주비 | C19: 호스팅 월이용료 | D19: 주식회사애드포시스 | E19: 환급 | F19: 46042 | G19: 16522000
B20: 외주비 | C20: 호스팅 월이용료 | D20: 주식회사애드포시스 | E20: 환급 | F20: 46073 | H20: 18150400
B21: 외주비 | C21: 호스팅 월이용료 | D21: 주식회사애드포시스 | E21: 환급 | F21: 46101 | I21: 17332200
B22: 외주비 | C22: 호스팅 월이용료 | D22: 주식회사애드포시스 | E22: 환급 | F22: 46132 | J22: 18800000
B23: 외주비 | C23: 제주관광공사 2025년 1월 운영비 | D23: (주)글로벌키타(Global Kita) | E23: 공공 | F23: 46052 | G23: 630000 | H23: 630000 | I23: 630000 | J23: 630000
B24: 외주비 | C24: 서울대 부모교육 (정율사관학원외 2개학원) | D24: 주식회사 에듀콘 | E24: 기타 | F24: 46052 | G24: 2254545 | H24: 9127273 | I24: 2727273 | J24: 2727273
B25: 외주비 | C25: 맑은소프트 교육 플랫폼 개발 비용 1월 1 X 16,666,000 | D25: 주식회사 유빅소프트 | E25: 전사 | F25: 46052 | G25: 16666000 | H25: 16666000 | I25: 16666000 | J25: 16666000
B26: 외주비 | C26: 맑은소프트LMS 영문 사용자 인터페이스 개발용역(잔금) | D26: 유빅소프트 | E26: 환급 | F26: 46078 | H26: 12500000
B27: 외주비 | C27: 월 유지보수 | D27: 플로즈 | E27: 환급 | F27: 46052 | G27: 14300000 | H27: 10650000 | I27: 4950000 | J27: 7900000 | V27: ='전체'!S6 -> 1014287821
B28: 외주비 | C28: FULL RACK 1 | D28: (주) 비아웹 | E28: 범용 | F28: 46053 | G28: 1900000 | H28: 1900000 | I28: 2050000 | J28: 2050000
B29: 외주비 | C29: CDN 서비스 이용료 | D29: (주)다날인프라랩 | E29: 환급 | F29: 46053 | G29: 2595900 | H29: 2922260 | I29: 3586020 | J29: 4088660
B30: 외주비 | C30: 화상솔루션 사용료 | D30: (주)새하컴즈 | E30: 범용 | F30: 46053 | G30: 2000000 | H30: 2000000 | I30: 2000000 | J30: 2000000
B31: 외주비 | C31: 수수료 1 X 1,256,416 | D31: 씨에스쉐어링 주식회사 | E31: 전사 | F31: 46053 | G31: 1256416 | H31: 1252300 | I31: 1252273 | J31: 1252164
B32: 외주비 | C32: 배송정보 추적 이용료 1 X 500,000 | D32: 주식회사 블룸에이아이 | E32: 범용 | F32: 46053 | G32: 580000 | H32: 580000 | I32: 580000 | J32: 580000
B33: 외주비 | C33: CDN 서비스 - 2026년 01월 서비스 이용분 | D33: 주식회사 스피디 | E33: 위캔디오 | F33: 46053 | G33: 4556800 | H33: 7127240 | I33: 8981540 | J33: 7159700
B34: 외주비 | C34: 이용료 맑은소프트 KLS 리셀링 | D34: 카테노이드 주식회사 | E34: 범용 | F34: 46053 | G34: 37009000 | H34: 38087000 | I34: 38282000 | J34: 36360000
B35: 외주비 | C35: 맑은이러닝서비스기술지원 | D35: 한스앤잔인터내셔널주식회사 | E35: 환급 | F35: 46053 | G35: 19666416 | H35: 8381007 | I35: 19606320 | J35: 7887695
B36: 외주비 | C36: 맑은소프트하이브리드앱유지보수(11,12,1월) | D36: 주식회사 옐로우윈 | E36: 범용 | F36: 46057 | H36: 2150000 | J36: 3400000
B37: 외주비 | C37: 한국능률협회 운영대행 서비스 1 X 960,000 | D37: 주식회사 온케어 | E37: 범용 | F37: 46062 | H37: 960000
B38: 외주비 | C38: 맑은소프트 ONS CDN 서비스 2월(1월 사용분) 1 X 3,000,000 | D38: 씨제이올리브네트웍스 주식회사 | E38: 위캔디오 | F38: 46073 | H38: 3000000 | I38: 3000000 | J38: 3321035
B39: 외주비 | C39: ssl 인증서구매(김서연팀장) | D39: 비트시럽 | E39: 전사 | F39: 46098 | I39: 2000000
B40: 외주비 | C40: 서울대한국어플러스 라이선스 정산수수료(12월 및 26년 1분기) | D40: 주식회사 에듀콘 | E40: 기타 | F40: 46112 | I40: 1981883
...

Sheet 광고선전비
B1: 구분 | C1: 내용 | D1: 거래처 | E1: 부서 | F1: 날짜 | G1: 1월 | H1: 2월 | I1: 3월 | J1: 4월 | K1: 5월 | L1: 6월 | M1: 7월 | N1: 8월 | O1: 9월 | P1: 10월 | Q1: 11월 | R1: 12월 | S1: 합계 | T1: 비중
B2: 광고선전비 | C2: 뉴스레터 발송 | D2: 나이스정보통신(주) | F2: 46033 | G2: 35455 | H2: 35455 | I2: 35455
B3: 광고선전비 | C3: 뉴스레터 이벤트 당첨자 경품 | D3: 엔에이치엔케이씨피주식회사 | F3: 46063 | H3: 39900
B4: 광고선전비 | C4: 고객만족도조사 참여자 경품 | D4: 엔에이치엔케이씨피주식회사 | F4: 46055 | H4: 315210
B5: 광고선전비 | C5: 매체광고(언론보도) 1 X 80,000 | D5: 주식회사 로애드 | F5: 46044 | G5: 80000 | I5: =240000+300000 -> 540000 | J5: 480000
B6: 광고선전비 | C6: 카탈로그 디자인 + 인쇄 | D6: 주식회사 브이에스엔씨(VSNC Co.,Ltd) | F6: 46045 | G6: 600000
B7: 광고선전비 | C7: 블로그 운영 대행 | D7: 주식회사 브이에스엔씨(VSNC Co.,Ltd) | F7: 46045 | G7: 1600000 | I7: 2800000 | J7: 1600000
B8: 광고선전비 | C8: 호스팅 1 X 150,000 | D8: 엔디소프트(주) | F8: 46048 | G8: 150000 | H8: 150000 | I8: 150000 | J8: 150000
B9: 광고선전비 | C9: 현수막 | D9: 토리디자인 | F9: 46048 | G9: 40000 | H9: 40000 | I9: 30000
B10: 광고선전비 | C10: 구글광고 | D10: 구글코리아 유한회사 | F10: 46053 | G10: =2781711+5199671 -> 7981382 | H10: 6931780 | I10: 8604649 | J10: 9062871
B11: 광고선전비 | C11: 네이버 광고 | D11: 네이버 주식회사 | F11: 46053 | G11: 6843920 | H11: 5033800 | I11: 9021980 | J11: 6434701
B12: 광고선전비 | C12: 사업소득 | D12: 사업소득 | F12: 46053 | G12: 3470000 | H12: 3150000 | I12: 3870000 | J12: 3740000
B13: 광고선전비 | C13: 인형탈 백팩 구매 | D13: 네이버파이낸셜주식회사 | F13: 46099 | I13: 88273
B14: 광고선전비 | C14: 물티슈제작 4,000 X 220 | D14: 주식회사 브이에스엔씨(VSNC Co.,Ltd) | F14: 46104 | I14: 880000

Sheet 비용통합
B1: 항목 | C1: 비용성격 | D1: 분류 | E1: 내용 | F1: 거래처 | G1: 부서 | H1: 절감가능여부 | I1: 절감 우선순위 | J1: 절감시기 | K1: 날짜 | L1: 1월 | M1: 2월 | N1: 3월 | O1: 4월 | P1: 5월(E)-절감X | Q1: 6월 | R1: 7월 | S1: 8월 | T1: 9월 | U1: 10월 | V1: 11월 | W1: 12월 | X1: 합계 | Y1: 비중
B2: 지급수수료 | C2: 변동 | E2: 카드수수료 | F2: 카드수수료 | H2: X | K2: 46023 | L2: 400 | M2: 400 | P2: 400
B3: 지급수수료 | C3: 고정 | D3: 사무실 | E3: 스탠드형 직수얼음정수기 1 | F3: SK매직(주) | H3: X | K3: 46023 | L3: 42636 | M3: 42636 | N3: 42636 | O3: 42636 | P3: =O3 -> 42636
B4: 지급수수료 | C4: 준변동 | D4: 서류 | E4: 민원발급수수료 | F4: 법원행정처 | H4: X | K4: 46027 | L4: 10000 | N4: 1000 | O4: 15000 | P4: 10000
B5: 지급수수료 | C5: 준변동 | D5: 서류 | E5: 민원발급수수료 | F5: （주) 엘지씨엔에스 | H5: X | K5: 46050 | L5: 1700 | O5: 1000 | P5: 1000
B6: 지급수수료 | C6: 준변동 | D6: 서류 | E6: 서류발급 | F6: 엔에이치엔케이씨피주식회사 | H6: X | K6: 46037 | L6: 8637 | M6: 36366 | N6: 2728 | P6: 10000
B7: 지급수수료 | C7: 일시 | D7: 서류 | E7: 수수료 | F7: 킨코스코리아(주) | H7: X | K7: 46040 | L7: 38310
B8: 지급수수료 | C8: 고정 | D8: 사무실 | E8: 텔레캅서비스 | F8: 케이티텔레캅(주) | H8: X | K8: 46027 | L8: 60000 | M8: 60000 | N8: 60000 | O8: 60000 | P8: =O8 -> 60000
B9: 지급수수료 | C9: 고정 | D9: 사무실 | E9: 프린터 기본 임대료 | F9: 마이컴센터 | H9: X | K9: 46027 | L9: 50000 | M9: 50000 | N9: 50000 | O9: 50000 | P9: =O9 -> 50000
B10: 지급수수료 | C10: 고정 | D10: 사무실 | E10: 2026년 1월 임대 D320 | F10: 신도H렌탈 | H10: X | K10: 46027 | L10: 70000 | M10: 70000 | N10: 70000 | O10: 70000 | P10: =O10 -> 70000
B11: 지급수수료 | C11: 준고정 | D11: 사무솔루션 | E11: 원티드스페이스 월간 이용료 | F11: 나이스정보통신(주) | H11: X | K11: 46027 | L11: 96000 | M11: 85000 | N11: 95285 | O11: 96160 | P11: =O11 -> 96160
B12: 지급수수료 | C12: 준변동 | D12: 사무실 | E12: 주차권구매 | F12: 대륭포스트타워1차입주자대표운영위원회 | H12: X | K12: 46027 | L12: 75000 | O12: 165000
B13: 지급수수료 | C13: 준변동 | D13: 사무솔루션 | E13: Adobe-회사계정 월간 구독료 | F13: 엔에이치엔케이씨피주식회사 | H13: X | K13: 46028 | L13: 104000 | M13: 104000 | N13: 104000 | O13: 94546 | P13: =O13 -> 94546
B14: 지급수수료 | C14: 준고정 | E14: 수수료 | F14: 나이스정보통신(주) | H14: 판단필요 | K14: 46028 | L14: 12638 | M14: 66265 | N14: 4455 | P14: 27786
B15: 지급수수료 | C15: 일시(일회) | E15: 수수료 | F15: 주식회사 코스트제로컨설팅 | H15: 세모 | K15: 46031 | L15: 6000000
B16: 지급수수료 | C16: 일시(일회) | E16: 수수료 | F16: 주식회사헥토파이낸셜 | H16: 판단필요 | K16: 46034 | L16: 145200
B17: 지급수수료 | C17: 변동 | E17: 수수료 | F17: 한국정보통신(주) | K17: 46098 | N17: 9091
B18: 지급수수료 | C18: 일시 | E18: 04월 경비청구 - 김상철 | F18: 주식회사헥토파이낸셜 | H18: O | K18: 46129 | O18: 7273
B19: 지급수수료 | C19: 일시 | D19: 사무솔루션 | E19: 부스터 패키지 - 가상계좌 1 X 522,327 | F19: ㈜사람인에이치알 | K19: 46029 | L19: 522327
B20: 지급수수료 | C20: 고정 | D20: 사무실 | E20: 렌탈료 1 | F20: 청호나이스(주) | K20: 46031 | L20: 45364 | M20: 45364 | N20: 45364 | O20: 45364 | P20: =O20 -> 45364
B21: 지급수수료 | C21: 변동 | D21: 서류 | E21: 서류 출력 | F21: 나이스정보통신(주) | K21: 46031 | L21: 5457 | M21: 23183
B22: 지급수수료 | C22: 일시 | E22: 스픽 구독 | F22: 나이스정보통신(주) | K22: 46031 | L22: 271819
B23: 지급수수료 | C23: 고정 | E23: 월구독 | F23: 쿠팡페이 주식회사 | K23: 46031 | L23: 7173 | M23: 7173 | N23: 7173 | O23: 7173 | P23: =O23 -> 7173
B24: 지급수수료 | C24: 고정 | E24: SMS100***16484 | F24: 신한 100-027-164841 | K24: 46034 | L24: 3000 | M24: 3000 | N24: 3000 | O24: 3000 | P24: =O24 -> 3000
B25: 지급수수료 | C25: 고정 | E25: SMS수수료 | F25: 우리 1005-002-038032 | K25: 46034 | L25: 1800 | M25: 1800 | N25: 1800 | O25: 1800 | P25: =O25 -> 1800
B26: 지급수수료 | C26: 준고정 | E26: 도메인 등록 | F26: 메가존㈜ | K26: 46036 | L26: 193200 | M26: 70000 | N26: 251791 | O26: 82000 | P26: 134000
B27: 지급수수료 | C27: 일시(년납) | E27: MALGN.ONHIWORKS.COM 연장(하이웍스) 1 X 456,000 | F27: (주) 가비아 | H27: X | K27: 46043 | L27: 456000
B28: 지급수수료 | C28: 고정 | E28: 식물관리 외 1 | F28: 플라워리치 | K28: 46045 | L28: 400000 | M28: 300000 | O28: 300000 | P28: =O28 -> 300000
B29: 지급수수료 | C29: 고정 | E29: 1월 기장료 | F29: 박앤장세무회계사무소 | K29: 46047 | L29: 250000 | M29: 250000 | N29: 250000 | O29: 250000 | P29: =O29 -> 250000
B30: 지급수수료 | C30: 일시(년납) | E30: 2025 세무조정 | F30: 박앤장세무회계사무소 | K30: 46106 | N30: 4950000
B31: 지급수수료 | C31: 일시(년납) | E31: Atlassian Jira(Cloud,S) | F31: 주식회사 오픈소스컨설팅 | H31: 계정 줄임(영업, 임원) | K31: 46048 | L31: 6396000
B32: 지급수수료 | C32: 일시(년납) | E32: Google Workspace Business Standard 연간 요금제 이용료 52 | F32: 주식회사 소프트웨어인라이프 | K32: 46050 | L32: 10083400 | N32: 175500
B33: 지급수수료 | C33: 고정 | E33: 정기청소 1 X 660,000 | F33: 탑 크린 월드 구로 | K33: 46051 | L33: 660000 | M33: 660000 | N33: 660000 | O33: 660000 | P33: =O33 -> 660000
B34: 지급수수료 | C34: 준고정 | E34: 월배치CMS수수료-malgnlms | F34: 효성에프엠에스(주) | K34: 46052 | L34: 779765 | M34: 591018 | N34: 575868 | O34: 679578 | P34: 656557
B35: 지급수수료 | C35: 고정 | E35: 월사용료-malgnlms | F35: 효성에프엠에스(주) | K35: 46052 | L35: 40600 | M35: 40632 | N35: 40800 | O35: 40576 | P35: 40652
B36: 지급수수료 | C36: 일시 | E36: 가상계좌 수수료대 | F36: (주)케이지모빌리언스 | K36: 46052 | L36: 250
B37: 지급수수료 | C37: 준변동 | E37: 전자지불수수료(bill_wecanglr7 2026/01) | F37: 토스페이먼츠 주식회사 | K37: 46053 | L37: 133108 | M37: 158448 | N37: 360937 | O37: 53582 | P37: 176000
B38: 지급수수료 | C38: 준변동 | E38: 전자지불수수료(MGN_snukorxi11 2026/02) | F38: 토스페이먼츠 주식회사 | K38: 46081 | M38: 9268 | N38: 11516 | O38: 5392 | P38: 8725
B39: 지급수수료 | C39: 고정 | E39: 우리은행 경리나라 2026.01월분 월정료외 1 X 66,000 | F39: 웹케시(주) | K39: 46053 | L39: 66000 | M39: 66000 | N39: 66000 | O39: 66000 | P39: =O39 -> 66000
B40: 지급수수료 | C40: ? | E40: 본인확인(갱신분) 1 X 1,000,000 | F40: NICE평가정보(주) | K40: 46056 | M40: 2206050
...
